<!DOCTYPE html PUBLIC"-//W3C//DTD XHTML 1.0 Transitional//EN""http://www.w3.org/TR/xhtml1/DTD/xhtml1-transitional.dtd"><html xmlns="http://www.w3.org/1999/xhtml"><head><meta http-equiv="Content-Type"content="text/html; charset=utf-8"/><title>日志信息</title><link rel="stylesheet" href="../css.css"/></head><body>[Log]<p>记录时间：2019/3/20 星期三 15:59:40</p><p>日志类型：错误信息</p><p>日志描述：IDX10709: JWT is not well formed: '{"readyState":4,"responseText":"{\"Code\":\"500\",\"Success\":false,\"Msg\":\"Value cannot be null.\\r\\nParameter name: value\"}","responseJSON":{"Code":"500","Success":false,"Msg":"Value cannot be null.\r\nParameter name: value"},"status":500,"statusText":"Internal Server Error"}'.
The token needs to be in JWS or JWE Compact Serialization Format. (JWS): 'EncodedHeader.EndcodedPayload.EncodedSignature'. (JWE): 'EncodedProtectedHeader.EncodedEncryptedKey.EncodedInitializationVector.EncodedCiphertext.EncodedAuthenticationTag'.</p><p>异常根源：System.IdentityModel.Tokens.Jwt</p><p>堆栈轨迹：   </br>at System.IdentityModel.Tokens.Jwt.JwtSecurityTokenHandler.ReadJwtToken(String token)
   </br>at RayPI.Helper.JwtHelper.SerializeJWT(String jwtStr) in D:\bk\Ray2.0\RayPI-master\RayPI.Helper\JwtHelper.cs:line 70
   </br>at RayPI.AuthHelp.JwtAuthorizationFilter.Invoke(HttpContext httpContext) in D:\bk\Ray2.0\RayPI-master\RayPI\AuthHelp\JWTAuthorizationFilter.cs:line 43
   </br>at Microsoft.AspNetCore.Authentication.AuthenticationMiddleware.<Invoke>d__6.MoveNext()
--- End of stack trace from previous location where exception was thrown ---
   </br>at System.Runtime.ExceptionServices.ExceptionDispatchInfo.Throw()
   </br>at System.Runtime.CompilerServices.TaskAwaiter.HandleNonSuccessAndDebuggerNotification(Task task)
   </br>at Swashbuckle.AspNetCore.SwaggerUI.SwaggerUIIndexMiddleware.<Invoke>d__3.MoveNext()
--- End of stack trace from previous location where exception was thrown ---
   </br>at System.Runtime.ExceptionServices.ExceptionDispatchInfo.Throw()
   </br>at System.Runtime.CompilerServices.TaskAwaiter.HandleNonSuccessAndDebuggerNotification(Task task)
   </br>at Swashbuckle.AspNetCore.Swagger.SwaggerMiddleware.<Invoke>d__6.MoveNext()
--- End of stack trace from previous location where exception was thrown ---
   </br>at System.Runtime.ExceptionServices.ExceptionDispatchInfo.Throw()
   </br>at System.Runtime.CompilerServices.TaskAwaiter.HandleNonSuccessAndDebuggerNotification(Task task)
   </br>at RayPI.ExceptionHelp.ExceptionFilter.<Invoke>d__2.MoveNext() in D:\bk\Ray2.0\RayPI-master\RayPI\ExceptionHelp\ExceptionFilter.cs:line 39</p><hr /><p>记录时间：2019/3/20 星期三 15:59:24</p><p>日志类型：错误信息</p><p>日志描述：Value cannot be null.
Parameter name: value</p><p>异常根源：System.Security.Claims</p><p>堆栈轨迹：   </br>at System.Security.Claims.Claim..ctor(String type, String value, String valueType, String issuer, String originalIssuer, ClaimsIdentity subject, String propertyKey, String propertyValue)
   </br>at System.Security.Claims.Claim..ctor(String type, String value)
   </br>at RayPI.Helper.JwtHelper.IssueJWT(TokenModel tokenModel) in D:\bk\Ray2.0\RayPI-master\RayPI.Helper\JwtHelper.cs:line 22
   </br>at RayPI.Controllers.SystemController.GetJWTStr(TokenModel tm) in D:\bk\Ray2.0\RayPI-master\RayPI\Controllers\SystemController.cs:line 52
   </br>at lambda_method(Closure , Object , Object[] )
   </br>at Microsoft.AspNetCore.Mvc.Internal.ControllerActionInvoker.<InvokeActionMethodAsync>d__12.MoveNext()
--- End of stack trace from previous location where exception was thrown ---
   </br>at System.Runtime.ExceptionServices.ExceptionDispatchInfo.Throw()
   </br>at System.Runtime.CompilerServices.TaskAwaiter.HandleNonSuccessAndDebuggerNotification(Task task)
   </br>at Microsoft.AspNetCore.Mvc.Internal.ControllerActionInvoker.<InvokeNextActionFilterAsync>d__10.MoveNext()
--- End of stack trace from previous location where exception was thrown ---
   </br>at System.Runtime.ExceptionServices.ExceptionDispatchInfo.Throw()
   </br>at Microsoft.AspNetCore.Mvc.Internal.ControllerActionInvoker.Rethrow(ActionExecutedContext context)
   </br>at Microsoft.AspNetCore.Mvc.Internal.ControllerActionInvoker.Next(State& next, Scope& scope, Object& state, Boolean& isCompleted)
   </br>at Microsoft.AspNetCore.Mvc.Internal.ControllerActionInvoker.<InvokeInnerFilterAsync>d__14.MoveNext()
--- End of stack trace from previous location where exception was thrown ---
   </br>at System.Runtime.ExceptionServices.ExceptionDispatchInfo.Throw()
   </br>at System.Runtime.CompilerServices.TaskAwaiter.HandleNonSuccessAndDebuggerNotification(Task task)
   </br>at Microsoft.AspNetCore.Mvc.Internal.ResourceInvoker.<InvokeNextResourceFilter>d__22.MoveNext()
--- End of stack trace from previous location where exception was thrown ---
   </br>at System.Runtime.ExceptionServices.ExceptionDispatchInfo.Throw()
   </br>at Microsoft.AspNetCore.Mvc.Internal.ResourceInvoker.Rethrow(ResourceExecutedContext context)
   </br>at Microsoft.AspNetCore.Mvc.Internal.ResourceInvoker.Next(State& next, Scope& scope, Object& state, Boolean& isCompleted)
   </br>at Microsoft.AspNetCore.Mvc.Internal.ResourceInvoker.<InvokeFilterPipelineAsync>d__17.MoveNext()
--- End of stack trace from previous location where exception was thrown ---
   </br>at System.Runtime.ExceptionServices.ExceptionDispatchInfo.Throw()
   </br>at System.Runtime.CompilerServices.TaskAwaiter.HandleNonSuccessAndDebuggerNotification(Task task)
   </br>at Microsoft.AspNetCore.Mvc.Internal.ResourceInvoker.<InvokeAsync>d__15.MoveNext()
--- End of stack trace from previous location where exception was thrown ---
   </br>at System.Runtime.ExceptionServices.ExceptionDispatchInfo.Throw()
   </br>at System.Runtime.CompilerServices.TaskAwaiter.HandleNonSuccessAndDebuggerNotification(Task task)
   </br>at Microsoft.AspNetCore.Builder.RouterMiddleware.<Invoke>d__4.MoveNext()
--- End of stack trace from previous location where exception was thrown ---
   </br>at System.Runtime.ExceptionServices.ExceptionDispatchInfo.Throw()
   </br>at System.Runtime.CompilerServices.TaskAwaiter.HandleNonSuccessAndDebuggerNotification(Task task)
   </br>at Microsoft.AspNetCore.Authentication.AuthenticationMiddleware.<Invoke>d__6.MoveNext()
--- End of stack trace from previous location where exception was thrown ---
   </br>at System.Runtime.ExceptionServices.ExceptionDispatchInfo.Throw()
   </br>at System.Runtime.CompilerServices.TaskAwaiter.HandleNonSuccessAndDebuggerNotification(Task task)
   </br>at Swashbuckle.AspNetCore.SwaggerUI.SwaggerUIIndexMiddleware.<Invoke>d__3.MoveNext()
--- End of stack trace from previous location where exception was thrown ---
   </br>at System.Runtime.ExceptionServices.ExceptionDispatchInfo.Throw()
   </br>at System.Runtime.CompilerServices.TaskAwaiter.HandleNonSuccessAndDebuggerNotification(Task task)
   </br>at Swashbuckle.AspNetCore.Swagger.SwaggerMiddleware.<Invoke>d__6.MoveNext()
--- End of stack trace from previous location where exception was thrown ---
   </br>at System.Runtime.ExceptionServices.ExceptionDispatchInfo.Throw()
   </br>at System.Runtime.CompilerServices.TaskAwaiter.HandleNonSuccessAndDebuggerNotification(Task task)
   </br>at RayPI.ExceptionHelp.ExceptionFilter.<Invoke>d__2.MoveNext() in D:\bk\Ray2.0\RayPI-master\RayPI\ExceptionHelp\ExceptionFilter.cs:line 39</p><hr /></body></html>